<mujoco>
    <compiler meshdir="../meshes" />

    <asset>
        <mesh name="cylinder" file="cylinder.STL" scale="0.001 0.001 0.001" />
        <mesh name="cylinder_name"  file="cylinder_name.STL" scale="0.001 0.001 0.001" />
        <mesh name="cylinder_collision" file="cylinder_collision.STL" scale="0.001 0.001 0.001" />
        <mesh name="piston"  file="piston.STL" scale="0.001 0.001 0.001" />
        <mesh name="piston_collision" file="piston_collision.STL" scale="0.001 0.001 0.001" />
    </asset>

    <worldbody>
        <body name="pneumatic_cylinder">
            <body name="cylinder">
                <geom type="mesh" mesh="cylinder"  contype="0" conaffinity="0" />
                <geom type="mesh" mesh="cylinder_name" rgba="0 1 0 1" />
                <geom type="mesh" mesh="cylinder_collision" rgba="1 0 0 1" />

                <body name="cylinder_sensor_retracted" pos="-0.45 -0.05 0" >
                    <geom type="cylinder" size="0.005 0.03" euler="90 0 0" rgba="1 1 0 1" contype="0" conaffinity="0" />
                </body>
    
                <body name="cylinder_sensor_extended" pos="0.45 -0.05 0" >
                    <geom type="cylinder" size="0.005 0.03" euler="90 0 0" rgba="1 1 0 1" contype="0" conaffinity="0" />
                </body>
            </body>

            <body name="piston_body">
                <geom type="mesh" mesh="piston" rgba="1 1 1 1"  contype="0" conaffinity="0" mass="0.1" />
                <joint name="piston_joint" type="slide" axis="1 0 0" range="0 1" damping="0.005" />
                <geom type="mesh" mesh="piston_collision" rgba="1 0 0 1" mass="0" />
            </body>
        </body>
    </worldbody>

    <actuator>
        <velocity name="pneumatic_mot" joint="piston_joint" ctrlrange="-2 2" />
    </actuator>

    <sensor>
        <normal name="pneumatic_retract" body1="cylinder_sensor_retracted" body2="piston_body"  />
        <normal name="pneumatic_extend" body1="cylinder_sensor_extended" body2="piston_body"  />
    </sensor>

</mujoco>